/**
 * Error Handler Hook for Message Generation Workflow
 * Task 9: Comprehensive error handling and user feedback
 */

import { useState, useCallback } from 'react';
import { useToast } from '@/hooks/use-toast';
import { MessageGenerationError } from '@/services/messageGenerationService';
import { ApiError } from '@/services/lambdaApiService';
import type { WorkflowError, ErrorRecoveryOptions, ErrorSeverity } from '@/types/index';

export const useErrorHandler = () => {
  const { toast } = useToast();
  const [currentError, setCurrentError] = useState<WorkflowError | null>(null);
  const [errorHistory, setErrorHistory] = useState<WorkflowError[]>([]);

  const categorizeError = useCallback((error: any): WorkflowError['type'] => {
    if (error instanceof MessageGenerationError) {
      if (error.status === 401) return 'authentication';
      if (error.status === 429) return 'rate_limit';
      if (error.status && error.status >= 400 && error.status < 500) return 'validation';
      if (error.status && error.status >= 500) return 'api';
    }
    
    if (error instanceof ApiError) {
      return 'api';
    }
    
    if (error.name === 'NetworkError' || error.message?.includes('network')) {
      return 'network';
    }
    
    return 'unknown';
  }, []);

  const getRecoveryOptions = useCallback((errorType: WorkflowError['type']): ErrorRecoveryOptions => {
    switch (errorType) {
      case 'network':
        return { retry: true, skip: true, stop: true, fallback: false };
      case 'api':
        return { retry: true, skip: true, stop: true, fallback: true };
      case 'validation':
        return { retry: false, skip: true, stop: true, fallback: false };
      case 'authentication':
        return { retry: true, skip: false, stop: true, fallback: false };
      case 'rate_limit':
        return { retry: true, skip: true, stop: true, fallback: false };
      default:
        return { retry: true, skip: true, stop: true, fallback: false };
    }
  }, []);

  const getErrorSeverity = useCallback((errorType: WorkflowError['type']): ErrorSeverity => {
    switch (errorType) {
      case 'authentication':
        return 'critical';
      case 'network':
        return 'high';
      case 'api':
        return 'medium';
      case 'rate_limit':
        return 'medium';
      case 'validation':
        return 'low';
      default:
        return 'medium';
    }
  }, []);

  const createWorkflowError = useCallback((
    error: any,
    connectionId?: string,
    connectionName?: string,
    retryCount: number = 0
  ): WorkflowError => {
    const errorType = categorizeError(error);
    const recoveryOptions = getRecoveryOptions(errorType);
    
    return {
      type: errorType,
      message: error.message || 'An unexpected error occurred',
      connectionId,
      connectionName,
      recoveryOptions,
      retryCount,
      timestamp: new Date().toISOString()
    };
  }, [categorizeError, getRecoveryOptions]);

  const handleError = useCallback((
    error: any,
    connectionId?: string,
    connectionName?: string,
    retryCount: number = 0
  ): Promise<'retry' | 'skip' | 'stop'> => {
    const workflowError = createWorkflowError(error, connectionId, connectionName, retryCount);
    setCurrentError(workflowError);
    setErrorHistory(prev => [...prev, workflowError]);

    const severity = getErrorSeverity(workflowError.type);
    
    return new Promise((resolve) => {
      const actions = [];
      
      if (workflowError.recoveryOptions.retry) {
        actions.push({
          label: 'Retry',
          action: () => resolve('retry'),
          variant: 'default' as const
        });
      }
      
      if (workflowError.recoveryOptions.skip) {
        actions.push({
          label: 'Skip',
          action: () => resolve('skip'),
          variant: 'outline' as const
        });
      }
      
      if (workflowError.recoveryOptions.stop) {
        actions.push({
          label: 'Stop',
          action: () => resolve('stop'),
          variant: 'destructive' as const
        });
      }

      // Show error toast with recovery options
      const errorTitle = connectionName 
        ? `Error processing ${connectionName}`
        : 'Message generation error';
      
      const errorDescription = workflowError.message + 
        (retryCount > 0 ? ` (Attempt ${retryCount + 1})` : '');

      toast({
        title: errorTitle,
        description: errorDescription,
        variant: severity === 'critical' || severity === 'high' ? 'destructive' : 'default'
      });

      // Auto-resolve after timeout if no user action
      setTimeout(() => {
        if (workflowError.recoveryOptions.skip) {
          resolve('skip');
        } else {
          resolve('stop');
        }
      }, 10000); // 10 second timeout
    });
  }, [createWorkflowError, getErrorSeverity, toast]);

  const clearError = useCallback(() => {
    setCurrentError(null);
  }, []);

  const showSuccessFeedback = useCallback((message: string, title: string = 'Success') => {
    toast({
      title,
      description: message,
      variant: 'default'
    });
  }, [toast]);

  const showWarningFeedback = useCallback((message: string, title: string = 'Warning') => {
    toast({
      title,
      description: message,
      variant: 'default'
    });
  }, [toast]);

  const showInfoFeedback = useCallback((message: string, title: string = 'Information') => {
    toast({
      title,
      description: message,
      variant: 'default'
    });
  }, [toast]);

  return {
    currentError,
    errorHistory,
    handleError,
    clearError,
    showSuccessFeedback,
    showWarningFeedback,
    showInfoFeedback
  };
};
